[2025-01-22T16:57:59.381+0000] {local_task_job_runner.py:123} INFO - ::group::Pre task execution logs
[2025-01-22T16:57:59.395+0000] {taskinstance.py:2613} INFO - Dependencies all met for dep_context=non-requeueable deps ti=<TaskInstance: nyc_taxi_pipeline.extract_data manual__2025-01-22T16:47:53.653420+00:00 [queued]>
[2025-01-22T16:57:59.401+0000] {taskinstance.py:2613} INFO - Dependencies all met for dep_context=requeueable deps ti=<TaskInstance: nyc_taxi_pipeline.extract_data manual__2025-01-22T16:47:53.653420+00:00 [queued]>
[2025-01-22T16:57:59.401+0000] {taskinstance.py:2866} INFO - Starting attempt 3 of 3
[2025-01-22T16:57:59.412+0000] {taskinstance.py:2889} INFO - Executing <Task(BashOperator): extract_data> on 2025-01-22 16:47:53.653420+00:00
[2025-01-22T16:57:59.418+0000] {warnings.py:112} WARNING - /home/***/.local/lib/python3.12/site-packages/***/task/task_runner/standard_task_runner.py:70: DeprecationWarning: This process (pid=227) is multi-threaded, use of fork() may lead to deadlocks in the child.
  pid = os.fork()

[2025-01-22T16:57:59.420+0000] {standard_task_runner.py:72} INFO - Started process 229 to run task
[2025-01-22T16:57:59.419+0000] {standard_task_runner.py:104} INFO - Running: ['***', 'tasks', 'run', 'nyc_taxi_pipeline', 'extract_data', 'manual__2025-01-22T16:47:53.653420+00:00', '--job-id', '15', '--raw', '--subdir', 'DAGS_FOLDER/nyc_taxi_pipeline_dag.py', '--cfg-path', '/tmp/tmpk4j7ez2n']
[2025-01-22T16:57:59.420+0000] {standard_task_runner.py:105} INFO - Job 15: Subtask extract_data
[2025-01-22T16:57:59.628+0000] {task_command.py:467} INFO - Running <TaskInstance: nyc_taxi_pipeline.extract_data manual__2025-01-22T16:47:53.653420+00:00 [running]> on host e1a318b4c5c9
[2025-01-22T16:57:59.688+0000] {taskinstance.py:3132} INFO - Exporting env vars: AIRFLOW_CTX_DAG_OWNER='***' AIRFLOW_CTX_DAG_ID='nyc_taxi_pipeline' AIRFLOW_CTX_TASK_ID='extract_data' AIRFLOW_CTX_EXECUTION_DATE='2025-01-22T16:47:53.653420+00:00' AIRFLOW_CTX_TRY_NUMBER='3' AIRFLOW_CTX_DAG_RUN_ID='manual__2025-01-22T16:47:53.653420+00:00'
[2025-01-22T16:57:59.689+0000] {logging_mixin.py:190} INFO - Task instance is in running state
[2025-01-22T16:57:59.690+0000] {logging_mixin.py:190} INFO -  Previous state of the Task instance: queued
[2025-01-22T16:57:59.690+0000] {logging_mixin.py:190} INFO - Current task name:extract_data state:running start_date:2025-01-22 16:57:59.395752+00:00
[2025-01-22T16:57:59.690+0000] {logging_mixin.py:190} INFO - Dag name:nyc_taxi_pipeline and current dag run status:running
[2025-01-22T16:57:59.690+0000] {taskinstance.py:731} INFO - ::endgroup::
[2025-01-22T16:57:59.691+0000] {subprocess.py:78} INFO - Tmp dir root location: /tmp
[2025-01-22T16:57:59.692+0000] {subprocess.py:88} INFO - Running command: ['/usr/bin/bash', '-c', 'python ../../extract-pipeline/grab_taxi_data.py']
[2025-01-22T16:57:59.705+0000] {subprocess.py:99} INFO - Output:
[2025-01-22T16:57:59.732+0000] {subprocess.py:106} INFO - python: can't open file '/tmp/***tmpiqumqffp/../../extract-pipeline/grab_taxi_data.py': [Errno 2] No such file or directory
[2025-01-22T16:57:59.735+0000] {subprocess.py:110} INFO - Command exited with return code 2
[2025-01-22T16:57:59.744+0000] {taskinstance.py:3311} ERROR - Task failed with exception
Traceback (most recent call last):
  File "/home/airflow/.local/lib/python3.12/site-packages/airflow/models/taskinstance.py", line 767, in _execute_task
    result = _execute_callable(context=context, **execute_callable_kwargs)
             ^^^^^^^^^^^^^^^^^^^^^^^^^^^^^^^^^^^^^^^^^^^^^^^^^^^^^^^^^^^^^
  File "/home/airflow/.local/lib/python3.12/site-packages/airflow/models/taskinstance.py", line 733, in _execute_callable
    return ExecutionCallableRunner(
           ^^^^^^^^^^^^^^^^^^^^^^^^
  File "/home/airflow/.local/lib/python3.12/site-packages/airflow/utils/operator_helpers.py", line 252, in run
    return self.func(*args, **kwargs)
           ^^^^^^^^^^^^^^^^^^^^^^^^^^
  File "/home/airflow/.local/lib/python3.12/site-packages/airflow/models/baseoperator.py", line 422, in wrapper
    return func(self, *args, **kwargs)
           ^^^^^^^^^^^^^^^^^^^^^^^^^^^
  File "/home/airflow/.local/lib/python3.12/site-packages/airflow/operators/bash.py", line 276, in execute
    raise AirflowException(
airflow.exceptions.AirflowException: Bash command failed. The command returned a non-zero exit code 2.
[2025-01-22T16:57:59.748+0000] {logging_mixin.py:190} INFO - Task instance in failure state
[2025-01-22T16:57:59.748+0000] {logging_mixin.py:190} INFO - Task start:2025-01-22 16:57:59.395752+00:00 end:2025-01-22 16:57:59.747910+00:00 duration:0.352158
[2025-01-22T16:57:59.749+0000] {logging_mixin.py:190} INFO - Task:<Task(BashOperator): extract_data> dag:<DAG: nyc_taxi_pipeline> dagrun:<DagRun nyc_taxi_pipeline @ 2025-01-22 16:47:53.653420+00:00: manual__2025-01-22T16:47:53.653420+00:00, state:running, queued_at: 2025-01-22 16:47:53.662945+00:00. externally triggered: True>
[2025-01-22T16:57:59.749+0000] {logging_mixin.py:190} INFO - Failure caused by Bash command failed. The command returned a non-zero exit code 2.
[2025-01-22T16:57:59.750+0000] {taskinstance.py:1225} INFO - Marking task as FAILED. dag_id=nyc_taxi_pipeline, task_id=extract_data, run_id=manual__2025-01-22T16:47:53.653420+00:00, execution_date=20250122T164753, start_date=20250122T165759, end_date=20250122T165759
[2025-01-22T16:57:59.759+0000] {taskinstance.py:340} INFO - ::group::Post task execution logs
[2025-01-22T16:57:59.760+0000] {standard_task_runner.py:124} ERROR - Failed to execute job 15 for task extract_data (Bash command failed. The command returned a non-zero exit code 2.; 229)
Traceback (most recent call last):
  File "/home/airflow/.local/lib/python3.12/site-packages/airflow/task/task_runner/standard_task_runner.py", line 117, in _start_by_fork
    ret = args.func(args, dag=self.dag)
          ^^^^^^^^^^^^^^^^^^^^^^^^^^^^^
  File "/home/airflow/.local/lib/python3.12/site-packages/airflow/cli/cli_config.py", line 49, in command
    return func(*args, **kwargs)
           ^^^^^^^^^^^^^^^^^^^^^
  File "/home/airflow/.local/lib/python3.12/site-packages/airflow/utils/cli.py", line 116, in wrapper
    return f(*args, **kwargs)
           ^^^^^^^^^^^^^^^^^^
  File "/home/airflow/.local/lib/python3.12/site-packages/airflow/cli/commands/task_command.py", line 483, in task_run
    task_return_code = _run_task_by_selected_method(args, _dag, ti)
                       ^^^^^^^^^^^^^^^^^^^^^^^^^^^^^^^^^^^^^^^^^^^^
  File "/home/airflow/.local/lib/python3.12/site-packages/airflow/cli/commands/task_command.py", line 256, in _run_task_by_selected_method
    return _run_raw_task(args, ti)
           ^^^^^^^^^^^^^^^^^^^^^^^
  File "/home/airflow/.local/lib/python3.12/site-packages/airflow/cli/commands/task_command.py", line 341, in _run_raw_task
    return ti._run_raw_task(
           ^^^^^^^^^^^^^^^^^
  File "/home/airflow/.local/lib/python3.12/site-packages/airflow/utils/session.py", line 97, in wrapper
    return func(*args, session=session, **kwargs)
           ^^^^^^^^^^^^^^^^^^^^^^^^^^^^^^^^^^^^^^
  File "/home/airflow/.local/lib/python3.12/site-packages/airflow/models/taskinstance.py", line 3005, in _run_raw_task
    return _run_raw_task(
           ^^^^^^^^^^^^^^
  File "/home/airflow/.local/lib/python3.12/site-packages/airflow/models/taskinstance.py", line 273, in _run_raw_task
    TaskInstance._execute_task_with_callbacks(
  File "/home/airflow/.local/lib/python3.12/site-packages/airflow/models/taskinstance.py", line 3159, in _execute_task_with_callbacks
    result = self._execute_task(context, task_orig)
             ^^^^^^^^^^^^^^^^^^^^^^^^^^^^^^^^^^^^^^
  File "/home/airflow/.local/lib/python3.12/site-packages/airflow/models/taskinstance.py", line 3183, in _execute_task
    return _execute_task(self, context, task_orig)
           ^^^^^^^^^^^^^^^^^^^^^^^^^^^^^^^^^^^^^^^
  File "/home/airflow/.local/lib/python3.12/site-packages/airflow/models/taskinstance.py", line 767, in _execute_task
    result = _execute_callable(context=context, **execute_callable_kwargs)
             ^^^^^^^^^^^^^^^^^^^^^^^^^^^^^^^^^^^^^^^^^^^^^^^^^^^^^^^^^^^^^
  File "/home/airflow/.local/lib/python3.12/site-packages/airflow/models/taskinstance.py", line 733, in _execute_callable
    return ExecutionCallableRunner(
           ^^^^^^^^^^^^^^^^^^^^^^^^
  File "/home/airflow/.local/lib/python3.12/site-packages/airflow/utils/operator_helpers.py", line 252, in run
    return self.func(*args, **kwargs)
           ^^^^^^^^^^^^^^^^^^^^^^^^^^
  File "/home/airflow/.local/lib/python3.12/site-packages/airflow/models/baseoperator.py", line 422, in wrapper
    return func(self, *args, **kwargs)
           ^^^^^^^^^^^^^^^^^^^^^^^^^^^
  File "/home/airflow/.local/lib/python3.12/site-packages/airflow/operators/bash.py", line 276, in execute
    raise AirflowException(
airflow.exceptions.AirflowException: Bash command failed. The command returned a non-zero exit code 2.
[2025-01-22T16:57:59.794+0000] {local_task_job_runner.py:266} INFO - Task exited with return code 1
[2025-01-22T16:57:59.946+0000] {taskinstance.py:3895} INFO - 0 downstream tasks scheduled from follow-on schedule check
[2025-01-22T16:57:59.949+0000] {local_task_job_runner.py:245} INFO - ::endgroup::
