[2025-01-22T16:12:58.268+0000] {local_task_job_runner.py:123} INFO - ::group::Pre task execution logs
[2025-01-22T16:12:58.281+0000] {taskinstance.py:2613} INFO - Dependencies all met for dep_context=non-requeueable deps ti=<TaskInstance: nyc_taxi_pipeline.extract_data scheduled__2025-01-21T00:00:00+00:00 [queued]>
[2025-01-22T16:12:58.287+0000] {taskinstance.py:2613} INFO - Dependencies all met for dep_context=requeueable deps ti=<TaskInstance: nyc_taxi_pipeline.extract_data scheduled__2025-01-21T00:00:00+00:00 [queued]>
[2025-01-22T16:12:58.287+0000] {taskinstance.py:2866} INFO - Starting attempt 3 of 3
[2025-01-22T16:12:58.299+0000] {taskinstance.py:2889} INFO - Executing <Task(BashOperator): extract_data> on 2025-01-21 00:00:00+00:00
[2025-01-22T16:12:58.305+0000] {warnings.py:112} WARNING - /home/***/.local/lib/python3.12/site-packages/***/task/task_runner/standard_task_runner.py:70: DeprecationWarning: This process (pid=239) is multi-threaded, use of fork() may lead to deadlocks in the child.
  pid = os.fork()

[2025-01-22T16:12:58.307+0000] {standard_task_runner.py:72} INFO - Started process 242 to run task
[2025-01-22T16:12:58.306+0000] {standard_task_runner.py:104} INFO - Running: ['***', 'tasks', 'run', 'nyc_taxi_pipeline', 'extract_data', 'scheduled__2025-01-21T00:00:00+00:00', '--job-id', '10', '--raw', '--subdir', 'DAGS_FOLDER/nyc_taxi_pipeline_dag.py', '--cfg-path', '/tmp/tmp4_a8duxe']
[2025-01-22T16:12:58.307+0000] {standard_task_runner.py:105} INFO - Job 10: Subtask extract_data
[2025-01-22T16:12:58.536+0000] {task_command.py:467} INFO - Running <TaskInstance: nyc_taxi_pipeline.extract_data scheduled__2025-01-21T00:00:00+00:00 [running]> on host e1a318b4c5c9
[2025-01-22T16:12:58.596+0000] {taskinstance.py:3132} INFO - Exporting env vars: AIRFLOW_CTX_DAG_OWNER='***' AIRFLOW_CTX_DAG_ID='nyc_taxi_pipeline' AIRFLOW_CTX_TASK_ID='extract_data' AIRFLOW_CTX_EXECUTION_DATE='2025-01-21T00:00:00+00:00' AIRFLOW_CTX_TRY_NUMBER='3' AIRFLOW_CTX_DAG_RUN_ID='scheduled__2025-01-21T00:00:00+00:00'
[2025-01-22T16:12:58.597+0000] {logging_mixin.py:190} INFO - Task instance is in running state
[2025-01-22T16:12:58.597+0000] {logging_mixin.py:190} INFO -  Previous state of the Task instance: queued
[2025-01-22T16:12:58.598+0000] {logging_mixin.py:190} INFO - Current task name:extract_data state:running start_date:2025-01-22 16:12:58.282002+00:00
[2025-01-22T16:12:58.598+0000] {logging_mixin.py:190} INFO - Dag name:nyc_taxi_pipeline and current dag run status:running
[2025-01-22T16:12:58.599+0000] {taskinstance.py:731} INFO - ::endgroup::
[2025-01-22T16:12:58.599+0000] {subprocess.py:78} INFO - Tmp dir root location: /tmp
[2025-01-22T16:12:58.601+0000] {subprocess.py:88} INFO - Running command: ['/usr/bin/bash', '-c', 'python ../extract-pipeline/grab_taxi_data.py']
[2025-01-22T16:12:58.619+0000] {subprocess.py:99} INFO - Output:
[2025-01-22T16:12:58.650+0000] {subprocess.py:106} INFO - python: can't open file '/tmp/***tmp9emnm6bz/../extract-pipeline/grab_taxi_data.py': [Errno 2] No such file or directory
[2025-01-22T16:12:58.653+0000] {subprocess.py:110} INFO - Command exited with return code 2
[2025-01-22T16:12:58.663+0000] {taskinstance.py:3311} ERROR - Task failed with exception
Traceback (most recent call last):
  File "/home/airflow/.local/lib/python3.12/site-packages/airflow/models/taskinstance.py", line 767, in _execute_task
    result = _execute_callable(context=context, **execute_callable_kwargs)
             ^^^^^^^^^^^^^^^^^^^^^^^^^^^^^^^^^^^^^^^^^^^^^^^^^^^^^^^^^^^^^
  File "/home/airflow/.local/lib/python3.12/site-packages/airflow/models/taskinstance.py", line 733, in _execute_callable
    return ExecutionCallableRunner(
           ^^^^^^^^^^^^^^^^^^^^^^^^
  File "/home/airflow/.local/lib/python3.12/site-packages/airflow/utils/operator_helpers.py", line 252, in run
    return self.func(*args, **kwargs)
           ^^^^^^^^^^^^^^^^^^^^^^^^^^
  File "/home/airflow/.local/lib/python3.12/site-packages/airflow/models/baseoperator.py", line 422, in wrapper
    return func(self, *args, **kwargs)
           ^^^^^^^^^^^^^^^^^^^^^^^^^^^
  File "/home/airflow/.local/lib/python3.12/site-packages/airflow/operators/bash.py", line 276, in execute
    raise AirflowException(
airflow.exceptions.AirflowException: Bash command failed. The command returned a non-zero exit code 2.
[2025-01-22T16:12:58.666+0000] {logging_mixin.py:190} INFO - Task instance in failure state
[2025-01-22T16:12:58.667+0000] {logging_mixin.py:190} INFO - Task start:2025-01-22 16:12:58.282002+00:00 end:2025-01-22 16:12:58.666426+00:00 duration:0.384424
[2025-01-22T16:12:58.667+0000] {logging_mixin.py:190} INFO - Task:<Task(BashOperator): extract_data> dag:<DAG: nyc_taxi_pipeline> dagrun:<DagRun nyc_taxi_pipeline @ 2025-01-21 00:00:00+00:00: scheduled__2025-01-21T00:00:00+00:00, state:running, queued_at: 2025-01-22 16:02:50.001406+00:00. externally triggered: False>
[2025-01-22T16:12:58.667+0000] {logging_mixin.py:190} INFO - Failure caused by Bash command failed. The command returned a non-zero exit code 2.
[2025-01-22T16:12:58.668+0000] {taskinstance.py:1225} INFO - Marking task as FAILED. dag_id=nyc_taxi_pipeline, task_id=extract_data, run_id=scheduled__2025-01-21T00:00:00+00:00, execution_date=20250121T000000, start_date=20250122T161258, end_date=20250122T161258
[2025-01-22T16:12:58.677+0000] {taskinstance.py:340} INFO - ::group::Post task execution logs
[2025-01-22T16:12:58.678+0000] {standard_task_runner.py:124} ERROR - Failed to execute job 10 for task extract_data (Bash command failed. The command returned a non-zero exit code 2.; 242)
Traceback (most recent call last):
  File "/home/airflow/.local/lib/python3.12/site-packages/airflow/task/task_runner/standard_task_runner.py", line 117, in _start_by_fork
    ret = args.func(args, dag=self.dag)
          ^^^^^^^^^^^^^^^^^^^^^^^^^^^^^
  File "/home/airflow/.local/lib/python3.12/site-packages/airflow/cli/cli_config.py", line 49, in command
    return func(*args, **kwargs)
           ^^^^^^^^^^^^^^^^^^^^^
  File "/home/airflow/.local/lib/python3.12/site-packages/airflow/utils/cli.py", line 116, in wrapper
    return f(*args, **kwargs)
           ^^^^^^^^^^^^^^^^^^
  File "/home/airflow/.local/lib/python3.12/site-packages/airflow/cli/commands/task_command.py", line 483, in task_run
    task_return_code = _run_task_by_selected_method(args, _dag, ti)
                       ^^^^^^^^^^^^^^^^^^^^^^^^^^^^^^^^^^^^^^^^^^^^
  File "/home/airflow/.local/lib/python3.12/site-packages/airflow/cli/commands/task_command.py", line 256, in _run_task_by_selected_method
    return _run_raw_task(args, ti)
           ^^^^^^^^^^^^^^^^^^^^^^^
  File "/home/airflow/.local/lib/python3.12/site-packages/airflow/cli/commands/task_command.py", line 341, in _run_raw_task
    return ti._run_raw_task(
           ^^^^^^^^^^^^^^^^^
  File "/home/airflow/.local/lib/python3.12/site-packages/airflow/utils/session.py", line 97, in wrapper
    return func(*args, session=session, **kwargs)
           ^^^^^^^^^^^^^^^^^^^^^^^^^^^^^^^^^^^^^^
  File "/home/airflow/.local/lib/python3.12/site-packages/airflow/models/taskinstance.py", line 3005, in _run_raw_task
    return _run_raw_task(
           ^^^^^^^^^^^^^^
  File "/home/airflow/.local/lib/python3.12/site-packages/airflow/models/taskinstance.py", line 273, in _run_raw_task
    TaskInstance._execute_task_with_callbacks(
  File "/home/airflow/.local/lib/python3.12/site-packages/airflow/models/taskinstance.py", line 3159, in _execute_task_with_callbacks
    result = self._execute_task(context, task_orig)
             ^^^^^^^^^^^^^^^^^^^^^^^^^^^^^^^^^^^^^^
  File "/home/airflow/.local/lib/python3.12/site-packages/airflow/models/taskinstance.py", line 3183, in _execute_task
    return _execute_task(self, context, task_orig)
           ^^^^^^^^^^^^^^^^^^^^^^^^^^^^^^^^^^^^^^^
  File "/home/airflow/.local/lib/python3.12/site-packages/airflow/models/taskinstance.py", line 767, in _execute_task
    result = _execute_callable(context=context, **execute_callable_kwargs)
             ^^^^^^^^^^^^^^^^^^^^^^^^^^^^^^^^^^^^^^^^^^^^^^^^^^^^^^^^^^^^^
  File "/home/airflow/.local/lib/python3.12/site-packages/airflow/models/taskinstance.py", line 733, in _execute_callable
    return ExecutionCallableRunner(
           ^^^^^^^^^^^^^^^^^^^^^^^^
  File "/home/airflow/.local/lib/python3.12/site-packages/airflow/utils/operator_helpers.py", line 252, in run
    return self.func(*args, **kwargs)
           ^^^^^^^^^^^^^^^^^^^^^^^^^^
  File "/home/airflow/.local/lib/python3.12/site-packages/airflow/models/baseoperator.py", line 422, in wrapper
    return func(self, *args, **kwargs)
           ^^^^^^^^^^^^^^^^^^^^^^^^^^^
  File "/home/airflow/.local/lib/python3.12/site-packages/airflow/operators/bash.py", line 276, in execute
    raise AirflowException(
airflow.exceptions.AirflowException: Bash command failed. The command returned a non-zero exit code 2.
[2025-01-22T16:12:58.722+0000] {local_task_job_runner.py:266} INFO - Task exited with return code 1
[2025-01-22T16:12:58.888+0000] {taskinstance.py:3895} INFO - 0 downstream tasks scheduled from follow-on schedule check
[2025-01-22T16:12:58.892+0000] {local_task_job_runner.py:245} INFO - ::endgroup::
