[2025-01-22T19:29:17.861+0000] {local_task_job_runner.py:123} INFO - ::group::Pre task execution logs
[2025-01-22T19:29:17.875+0000] {taskinstance.py:2613} INFO - Dependencies all met for dep_context=non-requeueable deps ti=<TaskInstance: nyc_taxi_pipeline.load_to_postgres manual__2025-01-22T19:23:03.054699+00:00 [queued]>
[2025-01-22T19:29:17.881+0000] {taskinstance.py:2613} INFO - Dependencies all met for dep_context=requeueable deps ti=<TaskInstance: nyc_taxi_pipeline.load_to_postgres manual__2025-01-22T19:23:03.054699+00:00 [queued]>
[2025-01-22T19:29:17.882+0000] {taskinstance.py:2866} INFO - Starting attempt 1 of 3
[2025-01-22T19:29:17.891+0000] {taskinstance.py:2889} INFO - Executing <Task(BashOperator): load_to_postgres> on 2025-01-22 19:23:03.054699+00:00
[2025-01-22T19:29:17.898+0000] {warnings.py:112} WARNING - /home/***/.local/lib/python3.12/site-packages/***/task/task_runner/standard_task_runner.py:70: DeprecationWarning: This process (pid=85) is multi-threaded, use of fork() may lead to deadlocks in the child.
  pid = os.fork()

[2025-01-22T19:29:17.900+0000] {standard_task_runner.py:72} INFO - Started process 87 to run task
[2025-01-22T19:29:17.899+0000] {standard_task_runner.py:104} INFO - Running: ['***', 'tasks', 'run', 'nyc_taxi_pipeline', 'load_to_postgres', 'manual__2025-01-22T19:23:03.054699+00:00', '--job-id', '35', '--raw', '--subdir', 'DAGS_FOLDER/nyc_taxi_pipeline_dag.py', '--cfg-path', '/tmp/tmpihfhv22a']
[2025-01-22T19:29:17.900+0000] {standard_task_runner.py:105} INFO - Job 35: Subtask load_to_postgres
[2025-01-22T19:29:17.937+0000] {task_command.py:467} INFO - Running <TaskInstance: nyc_taxi_pipeline.load_to_postgres manual__2025-01-22T19:23:03.054699+00:00 [running]> on host 313418e9474c
[2025-01-22T19:29:18.158+0000] {taskinstance.py:3132} INFO - Exporting env vars: AIRFLOW_CTX_DAG_OWNER='***' AIRFLOW_CTX_DAG_ID='nyc_taxi_pipeline' AIRFLOW_CTX_TASK_ID='load_to_postgres' AIRFLOW_CTX_EXECUTION_DATE='2025-01-22T19:23:03.054699+00:00' AIRFLOW_CTX_TRY_NUMBER='1' AIRFLOW_CTX_DAG_RUN_ID='manual__2025-01-22T19:23:03.054699+00:00'
[2025-01-22T19:29:18.159+0000] {logging_mixin.py:190} INFO - Task instance is in running state
[2025-01-22T19:29:18.159+0000] {logging_mixin.py:190} INFO -  Previous state of the Task instance: queued
[2025-01-22T19:29:18.160+0000] {logging_mixin.py:190} INFO - Current task name:load_to_postgres state:running start_date:2025-01-22 19:29:17.876345+00:00
[2025-01-22T19:29:18.160+0000] {logging_mixin.py:190} INFO - Dag name:nyc_taxi_pipeline and current dag run status:running
[2025-01-22T19:29:18.160+0000] {taskinstance.py:731} INFO - ::endgroup::
[2025-01-22T19:29:18.161+0000] {subprocess.py:78} INFO - Tmp dir root location: /tmp
[2025-01-22T19:29:18.162+0000] {subprocess.py:88} INFO - Running command: ['/usr/bin/bash', '-c', 'python /opt/***/staging-pipeline/load_to_postgres.py']
[2025-01-22T19:29:18.175+0000] {subprocess.py:99} INFO - Output:
[2025-01-22T19:29:19.137+0000] {subprocess.py:106} INFO - Traceback (most recent call last):
[2025-01-22T19:29:19.138+0000] {subprocess.py:106} INFO -   File "/opt/***/staging-pipeline/load_to_postgres.py", line 21, in <module>
[2025-01-22T19:29:19.139+0000] {subprocess.py:106} INFO -     parquet_files = sorted([f for f in os.listdir(DATA_DIR) if f.endswith(".parquet")], reverse=True)
[2025-01-22T19:29:19.140+0000] {subprocess.py:106} INFO -                                        ^^^^^^^^^^^^^^^^^^^^
[2025-01-22T19:29:19.140+0000] {subprocess.py:106} INFO - FileNotFoundError: [Errno 2] No such file or directory: '..\\data\\raw'
[2025-01-22T19:29:19.238+0000] {subprocess.py:110} INFO - Command exited with return code 1
[2025-01-22T19:29:19.248+0000] {taskinstance.py:3311} ERROR - Task failed with exception
Traceback (most recent call last):
  File "/home/airflow/.local/lib/python3.12/site-packages/airflow/models/taskinstance.py", line 767, in _execute_task
    result = _execute_callable(context=context, **execute_callable_kwargs)
             ^^^^^^^^^^^^^^^^^^^^^^^^^^^^^^^^^^^^^^^^^^^^^^^^^^^^^^^^^^^^^
  File "/home/airflow/.local/lib/python3.12/site-packages/airflow/models/taskinstance.py", line 733, in _execute_callable
    return ExecutionCallableRunner(
           ^^^^^^^^^^^^^^^^^^^^^^^^
  File "/home/airflow/.local/lib/python3.12/site-packages/airflow/utils/operator_helpers.py", line 252, in run
    return self.func(*args, **kwargs)
           ^^^^^^^^^^^^^^^^^^^^^^^^^^
  File "/home/airflow/.local/lib/python3.12/site-packages/airflow/models/baseoperator.py", line 422, in wrapper
    return func(self, *args, **kwargs)
           ^^^^^^^^^^^^^^^^^^^^^^^^^^^
  File "/home/airflow/.local/lib/python3.12/site-packages/airflow/operators/bash.py", line 276, in execute
    raise AirflowException(
airflow.exceptions.AirflowException: Bash command failed. The command returned a non-zero exit code 1.
[2025-01-22T19:29:19.254+0000] {logging_mixin.py:190} INFO - Task instance in failure state
[2025-01-22T19:29:19.255+0000] {logging_mixin.py:190} INFO - Task start:2025-01-22 19:29:17.876345+00:00 end:2025-01-22 19:29:19.254482+00:00 duration:1.378137
[2025-01-22T19:29:19.255+0000] {logging_mixin.py:190} INFO - Task:<Task(BashOperator): load_to_postgres> dag:<DAG: nyc_taxi_pipeline> dagrun:<DagRun nyc_taxi_pipeline @ 2025-01-22 19:23:03.054699+00:00: manual__2025-01-22T19:23:03.054699+00:00, state:running, queued_at: 2025-01-22 19:23:03.066467+00:00. externally triggered: True>
[2025-01-22T19:29:19.256+0000] {logging_mixin.py:190} INFO - Failure caused by Bash command failed. The command returned a non-zero exit code 1.
[2025-01-22T19:29:19.256+0000] {taskinstance.py:1225} INFO - Marking task as UP_FOR_RETRY. dag_id=nyc_taxi_pipeline, task_id=load_to_postgres, run_id=manual__2025-01-22T19:23:03.054699+00:00, execution_date=20250122T192303, start_date=20250122T192917, end_date=20250122T192919
[2025-01-22T19:29:19.268+0000] {taskinstance.py:340} INFO - ::group::Post task execution logs
[2025-01-22T19:29:19.269+0000] {standard_task_runner.py:124} ERROR - Failed to execute job 35 for task load_to_postgres (Bash command failed. The command returned a non-zero exit code 1.; 87)
Traceback (most recent call last):
  File "/home/airflow/.local/lib/python3.12/site-packages/airflow/task/task_runner/standard_task_runner.py", line 117, in _start_by_fork
    ret = args.func(args, dag=self.dag)
          ^^^^^^^^^^^^^^^^^^^^^^^^^^^^^
  File "/home/airflow/.local/lib/python3.12/site-packages/airflow/cli/cli_config.py", line 49, in command
    return func(*args, **kwargs)
           ^^^^^^^^^^^^^^^^^^^^^
  File "/home/airflow/.local/lib/python3.12/site-packages/airflow/utils/cli.py", line 116, in wrapper
    return f(*args, **kwargs)
           ^^^^^^^^^^^^^^^^^^
  File "/home/airflow/.local/lib/python3.12/site-packages/airflow/cli/commands/task_command.py", line 483, in task_run
    task_return_code = _run_task_by_selected_method(args, _dag, ti)
                       ^^^^^^^^^^^^^^^^^^^^^^^^^^^^^^^^^^^^^^^^^^^^
  File "/home/airflow/.local/lib/python3.12/site-packages/airflow/cli/commands/task_command.py", line 256, in _run_task_by_selected_method
    return _run_raw_task(args, ti)
           ^^^^^^^^^^^^^^^^^^^^^^^
  File "/home/airflow/.local/lib/python3.12/site-packages/airflow/cli/commands/task_command.py", line 341, in _run_raw_task
    return ti._run_raw_task(
           ^^^^^^^^^^^^^^^^^
  File "/home/airflow/.local/lib/python3.12/site-packages/airflow/utils/session.py", line 97, in wrapper
    return func(*args, session=session, **kwargs)
           ^^^^^^^^^^^^^^^^^^^^^^^^^^^^^^^^^^^^^^
  File "/home/airflow/.local/lib/python3.12/site-packages/airflow/models/taskinstance.py", line 3005, in _run_raw_task
    return _run_raw_task(
           ^^^^^^^^^^^^^^
  File "/home/airflow/.local/lib/python3.12/site-packages/airflow/models/taskinstance.py", line 273, in _run_raw_task
    TaskInstance._execute_task_with_callbacks(
  File "/home/airflow/.local/lib/python3.12/site-packages/airflow/models/taskinstance.py", line 3159, in _execute_task_with_callbacks
    result = self._execute_task(context, task_orig)
             ^^^^^^^^^^^^^^^^^^^^^^^^^^^^^^^^^^^^^^
  File "/home/airflow/.local/lib/python3.12/site-packages/airflow/models/taskinstance.py", line 3183, in _execute_task
    return _execute_task(self, context, task_orig)
           ^^^^^^^^^^^^^^^^^^^^^^^^^^^^^^^^^^^^^^^
  File "/home/airflow/.local/lib/python3.12/site-packages/airflow/models/taskinstance.py", line 767, in _execute_task
    result = _execute_callable(context=context, **execute_callable_kwargs)
             ^^^^^^^^^^^^^^^^^^^^^^^^^^^^^^^^^^^^^^^^^^^^^^^^^^^^^^^^^^^^^
  File "/home/airflow/.local/lib/python3.12/site-packages/airflow/models/taskinstance.py", line 733, in _execute_callable
    return ExecutionCallableRunner(
           ^^^^^^^^^^^^^^^^^^^^^^^^
  File "/home/airflow/.local/lib/python3.12/site-packages/airflow/utils/operator_helpers.py", line 252, in run
    return self.func(*args, **kwargs)
           ^^^^^^^^^^^^^^^^^^^^^^^^^^
  File "/home/airflow/.local/lib/python3.12/site-packages/airflow/models/baseoperator.py", line 422, in wrapper
    return func(self, *args, **kwargs)
           ^^^^^^^^^^^^^^^^^^^^^^^^^^^
  File "/home/airflow/.local/lib/python3.12/site-packages/airflow/operators/bash.py", line 276, in execute
    raise AirflowException(
airflow.exceptions.AirflowException: Bash command failed. The command returned a non-zero exit code 1.
[2025-01-22T19:29:19.318+0000] {local_task_job_runner.py:266} INFO - Task exited with return code 1
[2025-01-22T19:29:19.336+0000] {taskinstance.py:3895} INFO - 0 downstream tasks scheduled from follow-on schedule check
[2025-01-22T19:29:19.338+0000] {local_task_job_runner.py:245} INFO - ::endgroup::
